Workbook

Sheet START HERE
A1: PROPERTY MARKETPLACE — MASTER PROJECT ROADMAP & CHECKLIST
A2: Your single source of truth for building the marketplace, from research to launch to mobile app.
A5: HOW TO USE THIS WORKBOOK EVERY DAY
A6: 1. Open MASTER ROADMAP. | B6: Look at the dashboard at the top: it tells you instantly how many tasks are done, in progress, blocked and remaining. These numbers update themselves.
A7: 2. Filter by Phase. | B7: Click the filter arrow on the 'Phase No.' column and pick the phase you are working on. Do phases roughly in order — later phases depend on earlier ones.
A8: 3. Find your next task. | B8: Filter Status = NOT STARTED and Priority = CRITICAL. Check the 'Dependency' column: if the dependency is not DONE, do that first.
A9: 4. Update Status as you go. | B9: Click any Status cell and pick from the dropdown: NOT STARTED, IN PROGRESS, BLOCKED, REVIEW, DONE, DEFERRED. The dashboard and the PHASES sheet recalculate automatically.
A10: 5. Check DECISIONS LOG weekly. | B10: Anything marked DECISION REQUIRED is waiting for you. The project cannot finish until these are answered. Write your answer in 'Final Decision' and set the date.
A12: WHAT THE COLOUR TAGS MEAN
A13: OBSERVED FROM RESEARCH | B13: This comes from the attached research document — it was actually observed on a live competitor marketplace. Treat it as evidence.
A14: PROPOSED | B14: This is a recommendation, not an observation. It is a sensible default but you may change it.
A15: DECISION REQUIRED | B15: Nobody has decided this yet. It needs YOUR answer. See the DECISIONS LOG sheet.
A16: USER REQUIREMENT | B16: This came from your own instructions rather than from the research.
A18: THE SEVEN QUESTIONS THIS WORKBOOK ANSWERS
A19: 1. What is already done? | B19: MASTER ROADMAP dashboard + filter Status = DONE.
A20: 2. What should I work on next? | B20: MASTER ROADMAP: filter Status = NOT STARTED, sort by Phase No., check Dependency.
A21: 3. What is blocked? | B21: MASTER ROADMAP: filter Status = BLOCKED.
A22: 4. What depends on what? | B22: MASTER ROADMAP 'Dependency' column, and the PHASES sheet 'Dependencies' column.
A23: 5. What belongs to the MVP? | B23: MVP CHECKLIST sheet: filter MVP? = MVP.
A24: 6. What can wait? | B24: MVP CHECKLIST: filter MVP? = FUTURE. Then see POST-LAUNCH ROADMAP for when.
A25: 7. What decisions are outstanding? | B25: DECISIONS LOG: filter Decision Status = OPEN — DECISION REQUIRED.
A27: THE SHEETS, IN THE ORDER YOU WILL NEED THEM
A28: MASTER ROADMAP | B28: All 213 tasks with dependencies, effort, deliverables and acceptance criteria. Your daily working sheet.
A29: PHASES | B29: The 24 phases at a glance, with progress bars that calculate themselves from MASTER ROADMAP.
A30: MVP CHECKLIST | B30: What must be built for launch, and what must NOT be built yet. Your defence against scope creep.
A31: FEATURE CHECKLIST | B31: Every feature broken down by who uses it and what it needs (frontend, backend, database, API).
A32: WEBSITE PAGES | B32: Every page to design and build, with its URL and whether it needs SEO.
A33: USER FLOWS | B33: Step-by-step journeys for buyers, sellers and admins, including what can go wrong at each step.
A34: DATABASE | B34: The proposed tables, what each is for, and which are MVP versus later.
A35: API CHECKLIST | B35: Every planned API endpoint. Do not build these yet — this is the plan.
A36: UI/UX CHECKLIST | B36: The design system and interface work, from tokens to accessibility.
A37: SEO CHECKLIST | B37: URL structure, metadata, sitemaps and indexation. Read this BEFORE building any page.
A38: SECURITY CHECKLIST | B38: Controls that protect users, data and the business model.
A39: TESTING & QA | B39: What to test and what 'passing' means for each item.
... A47: GLOSSARY | B47: Every technical term in plain English. Start here if a word is unfamiliar.
A49: IMPORTANT RULES BUILT INTO THIS PLAN
A50: Supply before demand. | B50: Sellers and listings come before buyer features. An empty marketplace cannot be tested by buyers.
A51: Measure before you monetise. | B51: The lead loop is fully instrumented in Phase 10, but nothing is charged until after launch. You cannot price what you cannot measure.
A52: URLs before pages. | B52: The URL structure is decided in Phase 2, before any page is built. Retrofitting SEO-grade URLs later is effectively a rewrite.
A53: Performance before launch. | B53: Speed budgets are enforced in the build pipeline before going live, because performance debt compounds.
...

Sheet MASTER ROADMAP
A1: MASTER ROADMAP — complete task list, phase by phase
A2: Filter by Phase No. to see one phase at a time. Check 'Dependency' before starting a task. Update 'Status' from the dropdown — the dashboard below and the PHASES sheet recalculate automatically.
A3: PROGRESS DASHBOARD (these numbers update themselves)
A4: Total tasks | B4: =COUNTA($C$10:$C$222) -> 213 | D4: DONE | E4: =COUNTIF($J$10:$J$222,"DONE") -> 2 | G4: NOT STARTED | H4: =COUNTIF($J$10:$J$222,"NOT STARTED") -> 211
A5: IN PROGRESS | B5: =COUNTIF($J$10:$J$222,"IN PROGRESS") -> 0 | D5: BLOCKED | E5: =COUNTIF($J$10:$J$222,"BLOCKED") -> 0 | G5: REVIEW | H5: =COUNTIF($J$10:$J$222,"REVIEW") -> 0
A6: DEFERRED | B6: =COUNTIF($J$10:$J$222,"DEFERRED") -> 0 | D6: MVP tasks (Ph 0-20) | E6: =COUNTIFS($B$10:$B$222,"<=20") -> 196 | G6: Future tasks (Ph 21-23) | H6: =COUNTIFS($B$10:$B$222,">20") -> 17
A7: CRITICAL priority | B7: =COUNTIF($I$10:$I$222,"CRITICAL") -> 122 | D7: Decisions required | E7: =COUNTIF($P$10:$P$222,"DECISION REQUIRED") -> 15 | G7: OVERALL COMPLETION | H7: =IFERROR(COUNTIF($J$10:$J$222,"DONE")/COUNTA($C$10:$C$222),0) -> 0.0093896714
A9: Phase | B9: Phase No. | C9: Task ID | D9: Task | E9: Subtask | F9: Description | G9: Why It Is Needed | H9: Dependency | I9: Priority | J9: Status | K9: Owner | L9: Estimated Effort | M9: Deliverable | N9: Acceptance Criteria | O9: Notes | P9: Source
A10: Phase 0 — Research & Product Definition | B10: 0 | C10: 0.1 | D10: Competitor & market research | E10: Reverse-engineer a market leader | F10: Study the publicly observable structure, UX, URL grammar, SEO model and monetisation of an established marketplace. | G10: You cannot design an original product well without knowing what the category standard actually is. | H10: None | I10: CRITICAL | J10: DONE | K10: UNASSIGNED | L10: XL · 2–4 weeks | M10: Research specification document | N10: Document exists, every claim carries a confidence rating, sources cited. | O10: COMPLETE. See docs/99acres-reverse-engineering-and-marketplace-spec.md in this repository. | P10: OBSERVED FROM RESEARCH
A11: Phase 0 — Research & Product Definition | B11: 0 | C11: 0.2 | D11: Define the business model | E11: Confirm lead-generation model | F11: Confirm the product makes money from seller-side visibility and leads, not from buyer fees or transactions. | G11: Every downstream decision (data model, ranking, quotas) follows from this. Research confirms the incumbent monetises contact reveals. | H11: 0.1 | I11: CRITICAL | J11: DONE | K11: UNASSIGNED | L11: S · 1–2 days | M11: One-page business-model statement | N11: Written statement: who pays, for what, at which moment. | O11: Research confirms the monetisable event is the contact reveal, not the listing. | P11: OBSERVED FROM RESEARCH
A12: Phase 0 — Research & Product Definition | B12: 0 | C12: 0.3 | D12: Choose launch scope | E12: Pick cities and categories | F12: Decide which cities and which property categories the first version covers. | G12: A narrow launch is testable. A national launch across all categories is not. | H12: 0.2 | I12: CRITICAL | J12: NOT STARTED | K12: UNASSIGNED | L12: S · 1–2 days | M12: Written scope statement | N12: Named cities and categories, written down and agreed. | O12: Research proposes 3 cities, residential Buy + Rent only. YOU MUST CONFIRM which cities. See DECISIONS LOG D-11/D-12. | P12: DECISION REQUIRED
A13: Phase 0 — Research & Product Definition | B13: 0 | C13: 0.4 | D13: Define MVP boundary | E13: Agree what is NOT in v1 | F13: Write the explicit out-of-scope list so scope creep is visible when it happens. | G13: Unbounded MVPs never ship. The deferred list is as important as the included list. | H13: 0.3 | I13: CRITICAL | J13: NOT STARTED | K13: UNASSIGNED | L13: S · 1–2 days | M13: Signed-off MVP + out-of-scope list | N13: Both lists written; each deferred item has a target future phase. | O13: See MVP CHECKLIST sheet. Research §24 gives the starting boundary. | P13: OBSERVED FROM RESEARCH
A14: Phase 0 — Research & Product Definition | B14: 0 | C14: 0.5 | D14: Define success metrics | E14: Set measurable launch targets | F14: Agree the numbers that mean the MVP worked. | G14: Without targets you cannot tell success from activity. | H14: 0.4 | I14: HIGH | J14: NOT STARTED | K14: UNASSIGNED | L14: S · 1–2 days | M14: Metrics table with targets | N14: Each metric has a target number and a way to measure it. | O14: Research §24 proposes: ≥2,000 listings, search→PDP ≥25%, PDP→contact ≥8%, OTP completion ≥70%. | P14: PROPOSED
A15: Phase 0 — Research & Product Definition | B15: 0 | C15: 0.6 | D15: Legal and compliance review | E15: Engage a lawyer early | F15: Review data-protection obligations (India DPDP Act), listing liability, T&C, privacy policy, RERA advertising norms. | G15: This is not an engineering decision and getting it wrong after launch is expensive. | H15: 0.3 | I15: HIGH | J15: NOT STARTED | K15: UNASSIGNED | L15: M · 3–5 days | M15: Legal opinion + draft policies | N15: Lawyer has reviewed the data model and the T&C draft. | O15: Research §17.5 flags DPDP consent, retention, erasure; GST invoicing; RERA disclosure. Do not skip. | P15: OBSERVED FROM RESEARCH
A16: Phase 0 — Research & Product Definition | B16: 0 | C16: 0.7 | D16: Brand and naming | E16: Choose name, domain, identity | F16: Pick a product name, secure the domain and social handles, define brand direction. | G16: Needed before design, SEO and any public artefact. | H16: 0.3 | I16: HIGH | J16: NOT STARTED | K16: UNASSIGNED | L16: M · 3–5 days | M16: Name + registered domain | N16: Domain registered, name checked for trademark conflict. | O16: MUST be original. Do not reuse any competitor branding, wording or visual identity. | P16: DECISION REQUIRED
A17: Phase 0 — Research & Product Definition | B17: 0 | C17: 0.8 | D17: Supply acquisition plan | E17: Plan how to get first listings | F17: Decide how the first 2,000 listings arrive: manual outreach, agent partnerships, free posting drive. | G17: An empty marketplace cannot be tested by buyers. Supply must exist before demand. | H17: 0.3 | I17: CRITICAL | J17: NOT STARTED | K17: UNASSIGNED | L17: M · 3–5 days | M17: Written supply plan with owner | N17: A named plan with a weekly listing target. | O17: Research §23 sequencing: supply before demand. This is a business task, not an engineering task — it is the most common reason marketplaces fail. | P17: OBSERVED FROM RESEARCH
A18: Phase 1 — Project Foundation | B18: 1 | C18: 1.1 | D18: Create code repository | E18: Set up Git + GitHub | F18: Create the repository, add README, LICENSE, .gitignore and CODEOWNERS. | G18: Single source of truth for all code and history. | H18: 0.7 | I18: CRITICAL | J18: NOT STARTED | K18: UNASSIGNED | L18: S · 1–2 days | M18: Repository with initial commit | N18: Repo exists, you can clone and push. | P18: PROPOSED
A19: Phase 1 — Project Foundation | B19: 1 | C19: 1.2 | D19: Branch strategy | E19: Agree branching rules | F19: Define main/develop/feature branch rules and who can merge. | G19: Prevents broken code reaching production. | H19: 1.1 | I19: HIGH | J19: NOT STARTED | K19: UNASSIGNED | L19: S · 1–2 days | M19: Written branching policy in README | N19: Policy documented; main branch protected. | O19: PROPOSED: trunk-based with short feature branches + required PR review. | P19: PROPOSED
A20: Phase 1 — Project Foundation | B20: 1 | C20: 1.3 | D20: Choose frontend framework | E20: Confirm Next.js + TypeScript | F20: Confirm the frontend framework and language. | G20: Server-side rendering is a hard requirement for the SEO model; retrofitting it later is a rewrite. | H20: 0.4 | I20: CRITICAL | J20: NOT STARTED | K20: UNASSIGNED | L20: S · 1–2 days | M20: Recorded decision | N20: Decision written in DECISIONS LOG with date. | O20: Research §22 recommends Next.js (App Router) + React + TypeScript. See DECISIONS LOG D-01. | P20: DECISION REQUIRED
A21: Phase 1 — Project Foundation | B21: 1 | C21: 1.4 | D21: Choose backend framework | E21: Confirm backend language/framework | F21: Confirm backend framework and whether it is a modular monolith. | G21: Determines hiring, libraries and deployment for the whole project. | H21: 0.4 | I21: CRITICAL | J21: NOT STARTED | K21: UNASSIGNED | L21: S · 1–2 days | M21: Recorded decision | N21: Decision written in DECISIONS LOG with date. | O21: Research §22 recommends NestJS (TypeScript) modular monolith; Spring Boot if the team is Java-strong. See D-02. | P21: DECISION REQUIRED
A22: Phase 1 — Project Foundation | B22: 1 | C22: 1.5 | D22: Scaffold projects | E22: Create frontend + backend skeletons | F22: Create empty but runnable frontend and backend applications. | G22: Gives a working baseline everything else builds on. | H22: 1.3,1.4 | I22: CRITICAL | J22: NOT STARTED | K22: UNASSIGNED | L22: S · 1–2 days | M22: Two runnable apps | N22: Both start locally with one command. | P22: PROPOSED
A23: Phase 1 — Project Foundation | B23: 1 | C23: 1.6 | D23: Code quality tooling | E23: ESLint, Prettier, TypeScript strict | F23: Configure linting, formatting and strict type checking. | G23: Catches a large class of bugs before they are written. | H23: 1.5 | I23: HIGH | J23: NOT STARTED | K23: UNASSIGNED | L23: S · 1–2 days | M23: Lint + format config committed | N23: Lint runs clean on the scaffold. | P23: PROPOSED
A24: Phase 1 — Project Foundation | B24: 1 | C24: 1.7 | D24: Environment configuration | E24: Set up .env handling | F24: Define environment variables and a .env.example; never commit real secrets. | G24: Secrets in Git are the single most common serious security mistake. | H24: 1.5 | I24: CRITICAL | J24: NOT STARTED | K24: UNASSIGNED | L24: S · 1–2 days | M24: .env.example + secret policy | N24: No real secret exists in Git history. | O24: See SECURITY CHECKLIST and DEVOPS sheets. | P24: PROPOSED
A25: Phase 1 — Project Foundation | B25: 1 | C25: 1.8 | D25: Local development setup | E25: Docker Compose for DB + cache | F25: Run PostgreSQL and Redis locally with one command. | G25: Everyone develops against the same versions. | H25: 1.5 | I25: HIGH | J25: NOT STARTED | K25: UNASSIGNED | L25: S · 1–2 days | M25: docker-compose.yml | N25: `docker compose up` gives a working DB and cache. | P25: PROPOSED
A26: Phase 1 — Project Foundation | B26: 1 | C26: 1.9 | D26: CI pipeline (basic) | E26: GitHub Actions: lint, typecheck, test | F26: Run checks automatically on every pull request. | G26: Stops broken code merging while the codebase is still small. | H26: 1.6 | I26: HIGH | J26: NOT STARTED | K26: UNASSIGNED | L26: S · 1–2 days | M26: Green CI on the scaffold | N26: CI runs on PR and blocks merge on failure. | O26: Performance and Lighthouse gates are added later in Phase 16. | P26: PROPOSED
A27: Phase 1 — Project Foundation | B27: 1 | C27: 1.10 | D27: Project documentation | E27: Start a living README/architecture doc | F27: Document how to run, test and deploy the project. | G27: You will not remember this in three months. | H27: 1.5 | I27: MEDIUM | J27: NOT STARTED | K27: UNASSIGNED | L27: S · 1–2 days | M27: README with setup steps | N27: A new machine can run the project from the README alone. | P27: PROPOSED
A28: Phase 2 — Product Architecture | B28: 2 | C28: 2.1 | D28: Define module boundaries | E28: Agree the backend modules | F28: Split the backend into modules: identity, location, listing, search, lead, moderation, content, billing. | G28: Clear boundaries now make it cheap to split into services later, if ever needed. | H28: 1.4 | I28: CRITICAL | J28: NOT STARTED | K28: UNASSIGNED | L28: M · 3–5 days | M28: Module map diagram | N28: Every module has a written owner-of-data statement. | O28: Research §21.3 gives the module table. Modules talk via events, never by reading each other's tables. | P28: OBSERVED FROM RESEARCH
A29: Phase 2 — Product Architecture | B29: 2 | C29: 2.2 | D29: Define URL / route architecture | E29: Design the public URL structure | F29: Design every public route before building any page. | G29: The research's single highest-leverage finding: URL structure IS the product architecture for SEO. | H29: 0.3 | I29: CRITICAL | J29: NOT STARTED | K29: UNASSIGNED | L29: M · 3–5 days | M29: Route table (see WEBSITE PAGES sheet) | N29: Every planned page has an agreed final URL pattern. | O29: Research §16.5. Two surfaces: pretty SSR URLs (indexable) and /search?… (noindex). | P29: OBSERVED FROM RESEARCH
A30: Phase 2 — Product Architecture | B30: 2 | C30: 2.3 | D30: Decide rendering strategy | E30: SSR / SSG / ISR per route type | F30: Decide which pages are server-rendered, statically generated or incrementally regenerated. | G30: Directly determines SEO performance and hosting cost. | H30: 2.2 | I30: CRITICAL | J30: NOT STARTED | K30: UNASSIGNED | L30: S · 1–2 days | M30: Rendering decision per route type | N30: Each route type in WEBSITE PAGES has a rendering mode. | O30: Research §18.4: SSR for all indexable routes; personalisation must never block first paint. | P30: OBSERVED FROM RESEARCH
A31: Phase 2 — Product Architecture | B31: 2 | C31: 2.4 | D31: Choose database | E31: Confirm PostgreSQL + PostGIS | F31: Confirm the primary database and geospatial extension. | G31: One engine covers search, geo and transactions for the whole first phase. | H31: 1.4 | I31: CRITICAL | J31: NOT STARTED | K31: UNASSIGNED | L31: S · 1–2 days | M31: Recorded decision | N31: Decision in DECISIONS LOG. | O31: Research §22 recommends PostgreSQL 16 + PostGIS. See D-03. | P31: DECISION REQUIRED
A32: Phase 2 — Product Architecture | B32: 2 | C32: 2.5 | D32: Decide search approach | E32: Postgres now, OpenSearch later | F32: Confirm that MVP search runs on PostgreSQL and a search cluster is deferred. | G32: Avoids running a search cluster before there is data to justify it. | H32: 2.4 | I32: CRITICAL | J32: NOT STARTED | K32: UNASSIGNED | L32: S · 1–2 days | M32: Recorded decision + trigger | N32: Written trigger for when to migrate (listing count or latency). | O32: Research §13.3: Postgres to ~100k listings, then OpenSearch. See D-04. | P32: DECISION REQUIRED
A33: Phase 2 — Product Architecture | B33: 2 | C33: 2.6 | D33: Define the normalised filter object | E33: One filter shape for both surfaces | F33: Design a single canonical object that both the pretty URL and the query-param URL translate into. | G33: Prevents the two surfaces drifting apart and returning different results. | H33: 2.2 | I33: CRITICAL | J33: NOT STARTED | K33: UNASSIGNED | L33: M · 3–5 days | M33: Filter object schema | N33: Both URL forms parse to an identical object in tests. | O33: Research §6.2 — this is the core search design decision. | P33: OBSERVED FROM RESEARCH
A34: Phase 2 — Product Architecture | B34: 2 | C34: 2.7 | D34: Define ID strategy | E34: Public vs internal identifiers | F34: Decide how entity IDs look publicly and internally. | G34: Sequential public IDs leak business volume and allow enumeration. | H34: 2.4 | I34: HIGH | J34: NOT STARTED | K34: UNASSIGNED | L34: S · 1–2 days | M34: ID convention document | N34: Public IDs are non-sequential and prefixed per entity type. | O34: Research §11.1 observed typed prefixed IDs. PROPOSED: internal bigint + public prefixed short ID. | P34: PROPOSED
A35: Phase 2 — Product Architecture | B35: 2 | C35: 2.8 | D35: Define event/outbox pattern | E35: How modules communicate | F35: Design the transactional outbox and domain events. | G35: Keeps search index, notifications and analytics in sync without fragile dual writes. | H35: 2.1 | I35: HIGH | J35: NOT STARTED | K35: UNASSIGNED | L35: M · 3–5 days | M35: Event catalogue + outbox design | N35: Listing publish emits one event consumed by indexer and alerts. | O35: Research §21.4. | P35: OBSERVED FROM RESEARCH
A36: Phase 2 — Product Architecture | B36: 2 | C36: 2.9 | D36: Choose hosting and cloud | E36: Pick where it runs | F36: Decide hosting for frontend, backend, database and object storage. | G36: Affects cost, deployment and every DevOps task. | H36: 1.4 | I36: CRITICAL | J36: NOT STARTED | K36: UNASSIGNED | L36: S · 1–2 days | M36: Recorded decision + cost estimate | N36: Decision in DECISIONS LOG with a monthly cost estimate. | O36: Research §22: managed hosting first, Kubernetes only when justified. See D-07. | P36: DECISION REQUIRED
A37: Phase 2 — Product Architecture | B37: 2 | C37: 2.10 | D37: Write architecture document | E37: Consolidate all decisions | F37: Write one document describing the whole system. | G37: You are not an expert — this document is how you stay oriented. | H37: 2.1-2.9 | I37: HIGH | J37: NOT STARTED | K37: UNASSIGNED | L37: M · 3–5 days | M37: Architecture document | N37: A new developer can understand the system from it. | P37: PROPOSED
A38: Phase 3 — Design System & UI/UX | B38: 3 | C38: 3.1 | D38: Define design tokens | E38: Colour, type, spacing, radius scales | F38: Define the design variables that every component uses. | G38: Stops the UI drifting into inconsistency; makes dark mode and theming cheap. | H38: 1.5 | I38: CRITICAL | J38: NOT STARTED | K38: UNASSIGNED | L38: M · 3–5 days | M38: Token file (CSS variables) | N38: No component contains a raw colour or pixel value. | O38: Research §14.4/§14.5. MUST be an original visual identity — do not copy competitor colours or fonts. | P38: OBSERVED FROM RESEARCH
A39: Phase 3 — Design System & UI/UX | B39: 3 | C39: 3.2 | D39: Choose typography | E39: Font family and type scale | F39: Pick fonts, including Indic script coverage if localisation is ever planned. | G39: Font choice is hard to change later and affects performance. | H39: 3.1 | I39: HIGH | J39: NOT STARTED | K39: UNASSIGNED | L39: S · 1–2 days | M39: Type scale documented | N39: Scale defined; tabular numerals enabled for prices. | O39: Research §14.3 proposes a 1.250 scale and tabular numerals for price/area alignment. | P39: PROPOSED
A40: Phase 3 — Design System & UI/UX | B40: 3 | C40: 3.3 | D40: Build base components | E40: Button, input, select, chip, badge | F40: Build the smallest reusable UI pieces. | G40: Everything else is assembled from these. | H40: 3.1 | I40: CRITICAL | J40: NOT STARTED | K40: UNASSIGNED | L40: L · 1–2 weeks | M40: Component library v1 | N40: Each has all states: default, hover, focus, disabled, loading, error. | O40: Research §14.6. | P40: OBSERVED FROM RESEARCH
A41: Phase 3 — Design System & UI/UX | B41: 3 | C41: 3.4 | D41: Design the property card | E41: The most important component | F41: Design the card used in every result list. | G41: It is the unit of comparison; card quality drives click-through. | H41: 3.3 | I41: CRITICAL | J41: NOT STARTED | K41: UNASSIGNED | L41: M · 3–5 days | M41: Property card component | N41: Fixed image ratio, one primary action, area basis always labelled. | O41: Research §7.1. One filled primary button only — two competing buttons reduce clicks on both. | P41: OBSERVED FROM RESEARCH
...

Sheet PHASES
A1: PHASES — the whole project at a glance
A2: Progress is calculated automatically from the MASTER ROADMAP sheet. Do the phases roughly in order: later phases depend on earlier ones.
A4: Phase No. | B4: Phase Name | C4: Objective | D4: Main Deliverables | E4: Dependencies | F4: Estimated Duration | G4: Status | H4: Completion %
A5: 0 | B5: Phase 0 — Research & Product Definition | C5: Understand the market and decide exactly what to build. | D5: Research spec; business-model statement; launch scope; MVP boundary; success metrics; legal review; supply plan | E5: None | F5: 2–3 weeks | G5: =IF($H5>=1,"DONE",IF($H5>0,"IN PROGRESS","NOT STARTED")) -> IN PROGRESS | H5: =IFERROR(COUNTIFS('MASTER ROADMAP'!$B$10:$B$222,$A5,'MASTER ROADMAP'!$J$10:$J$222,"DONE")/COUNTIFS('MASTER ROADMAP'!$B$10:$B$222,$A5),0) -> 0.25
A6: 1 | B6: Phase 1 — Project Foundation | C6: Get a working, version-controlled, automatically-checked codebase. | D6: Repository; branch policy; scaffolds; linting; CI; local Docker setup | E6: Phase 0 | F6: 1–2 weeks | G6: =IF($H6>=1,"DONE",IF($H6>0,"IN PROGRESS","NOT STARTED")) -> NOT STARTED | H6: =IFERROR(COUNTIFS('MASTER ROADMAP'!$B$10:$B$222,$A6,'MASTER ROADMAP'!$J$10:$J$222,"DONE")/COUNTIFS('MASTER ROADMAP'!$B$10:$B$222,$A6),0) -> 0
A7: 2 | B7: Phase 2 — Product Architecture | C7: Decide the shape of the system before building any of it. | D7: Module map; URL architecture; rendering strategy; filter object; ID strategy; architecture document | E7: Phase 1 | F7: 1–2 weeks | G7: =IF($H7>=1,"DONE",IF($H7>0,"IN PROGRESS","NOT STARTED")) -> NOT STARTED | H7: =IFERROR(COUNTIFS('MASTER ROADMAP'!$B$10:$B$222,$A7,'MASTER ROADMAP'!$J$10:$J$222,"DONE")/COUNTIFS('MASTER ROADMAP'!$B$10:$B$222,$A7),0) -> 0
A8: 3 | B8: Phase 3 — Design System & UI/UX | C8: Build an original, consistent, accessible visual language. | D8: Design tokens; component library; property card; search UI; states; responsive rules; wireframes | E8: Phase 1 | F8: 3–4 weeks | G8: =IF($H8>=1,"DONE",IF($H8>0,"IN PROGRESS","NOT STARTED")) -> NOT STARTED | H8: =IFERROR(COUNTIFS('MASTER ROADMAP'!$B$10:$B$222,$A8,'MASTER ROADMAP'!$J$10:$J$222,"DONE")/COUNTIFS('MASTER ROADMAP'!$B$10:$B$222,$A8),0) -> 0
A9: 4 | B9: Phase 4 — Database & Backend Foundation | C9: Create the data model and the backend skeleton. | D9: Schema v1; migrations; seed data; indexes; API conventions; object storage; job queue | E9: Phase 2 | F9: 2–3 weeks | G9: =IF($H9>=1,"DONE",IF($H9>0,"IN PROGRESS","NOT STARTED")) -> NOT STARTED | H9: =IFERROR(COUNTIFS('MASTER ROADMAP'!$B$10:$B$222,$A9,'MASTER ROADMAP'!$J$10:$J$222,"DONE")/COUNTIFS('MASTER ROADMAP'!$B$10:$B$222,$A9),0) -> 0
A10: 5 | B10: Phase 5 — User Authentication | C10: Let people register and log in securely by phone. | D10: OTP login; sessions; roles; authorization; profile; account deletion | E10: Phase 4 | F10: 2 weeks | G10: =IF($H10>=1,"DONE",IF($H10>0,"IN PROGRESS","NOT STARTED")) -> NOT STARTED | H10: =IFERROR(COUNTIFS('MASTER ROADMAP'!$B$10:$B$222,$A10,'MASTER ROADMAP'!$J$10:$J$222,"DONE")/COUNTIFS('MASTER ROADMAP'!$B$10:$B$222,$A10),0) -> 0
A11: 6 | B11: Phase 6 — Location & Property Data | C11: Build the place hierarchy everything else depends on. | D11: Gazetteer; aliases; slugs; typeahead; PostGIS; property-type and amenity taxonomies | E11: Phase 4 | F11: 2–3 weeks | G11: =IF($H11>=1,"DONE",IF($H11>0,"IN PROGRESS","NOT STARTED")) -> NOT STARTED | H11: =IFERROR(COUNTIFS('MASTER ROADMAP'!$B$10:$B$222,$A11,'MASTER ROADMAP'!$J$10:$J$222,"DONE")/COUNTIFS('MASTER ROADMAP'!$B$10:$B$222,$A11),0) -> 0
A12: 7 | B12: Phase 7 — Seller / Owner Property Posting | C12: Let an owner list a property from a phone in under 8 minutes. | D12: Posting wizard; autosave; media pipeline; sanitisation; completeness score; publish + quota | E12: Phases 5, 6 | F12: 3–4 weeks | G12: =IF($H12>=1,"DONE",IF($H12>0,"IN PROGRESS","NOT STARTED")) -> NOT STARTED | H12: =IFERROR(COUNTIFS('MASTER ROADMAP'!$B$10:$B$222,$A12,'MASTER ROADMAP'!$J$10:$J$222,"DONE")/COUNTIFS('MASTER ROADMAP'!$B$10:$B$222,$A12),0) -> 0
A13: 8 | B13: Phase 8 — Property Search & Filters | C13: Let buyers find what they want, fast, without losing state. | D13: Search service; facets; sorting; ranking; both result surfaces; pagination; zero-result recovery | E13: Phases 6, 7 | F13: 3–4 weeks | G13: =IF($H13>=1,"DONE",IF($H13>0,"IN PROGRESS","NOT STARTED")) -> NOT STARTED | H13: =IFERROR(COUNTIFS('MASTER ROADMAP'!$B$10:$B$222,$A13,'MASTER ROADMAP'!$J$10:$J$222,"DONE")/COUNTIFS('MASTER ROADMAP'!$B$10:$B$222,$A13),0) -> 0
A14: 9 | B14: Phase 9 — Property Detail Page | C14: Answer the buyer's questions and lead them to contact. | D14: PDP; gallery; sticky contact; details; static map; seller card; save | E14: Phases 3, 8 | F14: 2–3 weeks | G14: =IF($H14>=1,"DONE",IF($H14>0,"IN PROGRESS","NOT STARTED")) -> NOT STARTED | H14: =IFERROR(COUNTIFS('MASTER ROADMAP'!$B$10:$B$222,$A14,'MASTER ROADMAP'!$J$10:$J$222,"DONE")/COUNTIFS('MASTER ROADMAP'!$B$10:$B$222,$A14),0) -> 0
A15: 10 | B15: Phase 10 — Leads / Enquiry / Contact Reveal | C15: Close the loop: deliver a measured lead to the seller. | D15: Inquiry model; enquiry form; OTP reveal; dedupe; rate limits; lead inbox; notifications; funnel events | E15: Phases 5, 9 | F15: 2–3 weeks | G15: =IF($H15>=1,"DONE",IF($H15>0,"IN PROGRESS","NOT STARTED")) -> NOT STARTED | H15: =IFERROR(COUNTIFS('MASTER ROADMAP'!$B$10:$B$222,$A15,'MASTER ROADMAP'!$J$10:$J$222,"DONE")/COUNTIFS('MASTER ROADMAP'!$B$10:$B$222,$A15),0) -> 0
A16: 11 | B16: Phase 11 — User Dashboard | C16: Give both sides a home base. | D16: Dashboard shell; my listings; saved properties; listing analytics; notification preferences | E16: Phases 7, 10 | F16: 1–2 weeks | G16: =IF($H16>=1,"DONE",IF($H16>0,"IN PROGRESS","NOT STARTED")) -> NOT STARTED | H16: =IFERROR(COUNTIFS('MASTER ROADMAP'!$B$10:$B$222,$A16,'MASTER ROADMAP'!$J$10:$J$222,"DONE")/COUNTIFS('MASTER ROADMAP'!$B$10:$B$222,$A16),0) -> 0
... A28: 23 | B28: Phase 23 — Native Mobile App | C28: Build native apps only if the data justifies them. | D28: Technology decision; mobile design; buyer journey; posting + verification; store release; release process | E28: Phase 22 | F28: 8–12 weeks | G28: =IF($H28>=1,"DONE",IF($H28>0,"IN PROGRESS","NOT STARTED")) -> NOT STARTED | H28: =IFERROR(COUNTIFS('MASTER ROADMAP'!$B$10:$B$222,$A28,'MASTER ROADMAP'!$J$10:$J$222,"DONE")/COUNTIFS('MASTER ROADMAP'!$B$10:$B$222,$A28),0) -> 0

Sheet MVP CHECKLIST
A1: MVP CHECKLIST — what to build now, and what NOT to build yet
A2: Filter MVP? = MVP for launch scope. Filter MVP? = FUTURE to see what is deliberately deferred and when it returns. This sheet is your defence against scope creep.
A4: Feature | B4: Category | C4: MVP? | D4: Priority | E4: Reason | F4: Dependencies | G4: Status | H4: Future Phase | I4: Source
A5: Intent tabs (Buy / Rent) | B5: Search | C5: MVP | D5: CRITICAL | E5: Buy and Rent are different products with different filters and economics; separating them is foundational. | F5: Phase 6 | G5: NOT STARTED | H5: — | I5: OBSERVED FROM RESEARCH
A6: Multi-select location typeahead | B6: Search | C6: MVP | D6: CRITICAL | E6: Real users search several localities at once; the entire funnel starts here. | F6: Gazetteer (6.1) | G6: NOT STARTED | H6: — | I6: OBSERVED FROM RESEARCH
A7: Faceted filters (budget, BHK, type, area, furnishing, status, posted-by, verified) | B7: Search | C7: MVP | D7: CRITICAL | E7: Core of the product. Research §6.3 defines the full set. | F7: Phase 8 | G7: NOT STARTED | H7: — | I7: OBSERVED FROM RESEARCH
A8: Sorting (relevance, price up/down, newest) | B8: Search | C8: MVP | D8: CRITICAL | E8: Users distrust results that ignore an explicit sort. | F8: Phase 8 | G8: NOT STARTED | H8: — | I8: OBSERVED FROM RESEARCH
A9: Filter state never lost on change or error | B9: Search | C9: MVP | D9: CRITICAL | E9: The incumbent's most-complained-about failure. This is our differentiator. | F9: Phase 8 | G9: NOT STARTED | H9: — | I9: OBSERVED FROM RESEARCH
A10: Result cards | B10: Property | C10: MVP | D10: CRITICAL | E10: The unit of comparison; drives click-through. | F10: Phase 3 | G10: NOT STARTED | H10: — | I10: OBSERVED FROM RESEARCH
A11: SEO landing pages with path pagination | B11: SEO | C11: MVP | D11: CRITICAL | E11: Primary acquisition channel; cannot be retrofitted. | F11: Phase 14 | G11: NOT STARTED | H11: — | I11: OBSERVED FROM RESEARCH
A12: Property detail page | B12: Property | C12: MVP | D12: CRITICAL | E12: Where the decision and the lead happen. | F12: Phase 9 | G12: NOT STARTED | H12: — | I12: OBSERVED FROM RESEARCH
A13: Image gallery | B13: Property | C13: MVP | D13: CRITICAL | E13: Photos are the most-used element on the page. | F13: Phase 9 | G13: NOT STARTED | H13: — | I13: OBSERVED FROM RESEARCH
A14: Static location map on the detail page | B14: Property | C14: MVP | D14: HIGH | E14: Location is the primary decision factor. NOTE: this is a static map, NOT interactive map search. | F14: Phase 6, 9 | G14: NOT STARTED | H14: — | I14: OBSERVED FROM RESEARCH
A15: Save / shortlist | B15: Buyer | C15: MVP | D15: CRITICAL | E15: Primary retention action in a months-long decision. | F15: Phase 9 | G15: NOT STARTED | H15: — | I15: OBSERVED FROM RESEARCH
... A63: Community Q&A / editorial engine | B63: Content | C63: FUTURE | D63: LOW | E63: Long-tail SEO value but high ongoing editorial cost. | F63: Phase 14 | G63: NOT STARTED | H63: v2.0 | I63: OBSERVED FROM RESEARCH

Sheet FEATURE CHECKLIST
A1: FEATURE CHECKLIST — every feature, and what it needs to be built
A2: Grouped by who uses it. 'Frontend / Backend / Database / API / Third-party' tell you which parts of the system each feature touches.
A4: Feature | B4: User Type | C4: Description | D4: MVP/Future | E4: Frontend | F4: Backend | G4: Database | H4: API | I4: Third-party service | J4: Dependency | K4: Status | L4: Source
A5: Browse by intent (Buy/Rent) | B5: Buyer | C5: Switch the whole search context between buying and renting. | D5: MVP | E5: Yes | F5: Yes | G5: PROPERTY | H5: GET /search | I5: — | J5: Phase 6 | K5: NOT STARTED | L5: OBSERVED FROM RESEARCH
A6: Location typeahead | B6: Buyer | C6: Search-as-you-type across cities, localities and societies. | D6: MVP | E6: Yes | F6: Yes | G6: LOCATION, PLACE_SUGGEST | H6: GET /places/suggest | I6: — | J6: Gazetteer | K6: NOT STARTED | L6: OBSERVED FROM RESEARCH
A7: Faceted search | B7: Buyer | C7: Filter results across many dimensions with live counts. | D7: MVP | E7: Yes | F7: Yes | G7: PROPERTY, LOCATION | H7: GET /search, GET /search/facets | I7: — | J7: Phase 8 | K7: NOT STARTED | L7: OBSERVED FROM RESEARCH
A8: Sort results | B8: Buyer | C8: Order results by relevance, price or recency. | D8: MVP | E8: Yes | F8: Yes | G8: PROPERTY | H8: GET /search | I8: — | J8: Phase 8 | K8: NOT STARTED | L8: OBSERVED FROM RESEARCH
A9: Infinite scroll results | B9: Buyer | C9: Load more results as the user scrolls on the app surface. | D9: MVP | E9: Yes | F9: Yes | G9: PROPERTY | H9: GET /search?page= | I9: — | J9: Phase 8 | K9: NOT STARTED | L9: OBSERVED FROM RESEARCH
A10: Crawlable paginated pages | B10: Buyer | C10: Path-based result pages that search engines can index. | D10: MVP | E10: Yes | F10: Yes | G10: PROPERTY | H10: SSR route | I10: — | J10: Phase 14 | K10: NOT STARTED | L10: OBSERVED FROM RESEARCH
A11: Property detail view | B11: Buyer | C11: Full listing information on one page. | D11: MVP | E11: Yes | F11: Yes | G11: PROPERTY, PROPERTY_MEDIA, AMENITY | H11: GET /properties/{id} | I11: — | J11: Phase 9 | K11: NOT STARTED | L11: OBSERVED FROM RESEARCH
A12: Image gallery | B12: Buyer | C12: Browse listing photos including full-screen view. | D12: MVP | E12: Yes | F12: No | G12: PROPERTY_MEDIA | H12: included in PDP | I12: CDN | J12: Phase 9 | K12: NOT STARTED | L12: OBSERVED FROM RESEARCH
A13: Static location map | B13: Buyer | C13: See where the property is on a map. | D13: MVP | E13: Yes | F13: No | G13: PROPERTY (geo) | H13: included in PDP | I13: Maps provider | J13: D-06 | K13: NOT STARTED | L13: OBSERVED FROM RESEARCH
A14: Save / shortlist | B14: Buyer | C14: Keep a list of properties to revisit. | D14: MVP | E14: Yes | F14: Yes | G14: FAVORITE | H14: POST/DELETE /favorites | I14: — | J14: Phase 5, 9 | K14: NOT STARTED | L14: OBSERVED FROM RESEARCH
A15: Send enquiry | B15: Buyer | C15: Message the seller about a listing. | D15: MVP | E15: Yes | F15: Yes | G15: INQUIRY | H15: POST /inquiries | I15: — | J15: Phase 10 | K15: NOT STARTED | L15: OBSERVED FROM RESEARCH
... A73: EMI calculator | B73: Content | C73: Estimate monthly loan payments. | D73: FUTURE | E73: Yes | F73: No | G73: — | H73: client-side | I73: — | J73: v2.2 | K73: NOT STARTED | L73: OBSERVED FROM RESEARCH

Sheet WEBSITE PAGES
A1: WEBSITE PAGES — every page to design and build
A2: URL patterns follow the SEO architecture proposed in the research. Decide these URLs in Phase 2, BEFORE building any page — changing them after launch costs search ranking.
A4: Page name | B4: URL pattern | C4: Purpose | D4: User type | E4: SEO required? | F4: Dynamic/Static | G4: Required components | H4: API/data required | I4: Mobile required? | J4: Status | K4: Source
A5: Homepage | B5: / | C5: Route the visitor into a typed intent plus a place, as fast as possible. | D5: All | E5: Yes | F5: Dynamic (SSR + cached) | G5: Header, intent tabs, hero search, quick chips, recommended rail, budget tiles, locality cards, owner CTA, SEO footer | H5: Suggest API, popular localities, recommended listings | I5: Yes | J5: NOT STARTED | K5: OBSERVED FROM RESEARCH
A6: Search results — SEO landing | B6: /{intent}/{city}[/{locality}][/{filter-slug}] | C6: Indexable landing page for a specific search intent; the main acquisition channel. | D6: Buyer/Tenant | E6: Yes | F6: Dynamic (SSR + ISR) | G6: Breadcrumb, H1 with count, filter rail, sort, chips, result cards, pagination, SEO copy, internal links, FAQ | H6: Search API, facet counts, internal link clusters | I6: Yes | J6: NOT STARTED | K6: OBSERVED FROM RESEARCH
A7: Search results — paginated | B7: /{intent}/{city}/.../page/{n} | C7: Crawlable deep pages so inventory beyond page 1 can be indexed. | D7: Buyer/Tenant | E7: Yes | F7: Dynamic (SSR) | G7: Same as landing page plus prev/next links | H7: Search API with offset | I7: Yes | J7: NOT STARTED | K7: OBSERVED FROM RESEARCH
A8: Search — interactive app surface | B8: /search?… | C8: Fast, stateful filtering without page reloads. Deliberately NOT indexed. | D8: Buyer/Tenant | E8: No (noindex) | F8: Dynamic (client + API) | G8: Filter panel/sheet, chips, sort, infinite scroll, result count | H8: Search API, facet API | I8: Yes | J8: NOT STARTED | K8: OBSERVED FROM RESEARCH
A9: Property detail | B9: /property/{slug}-p{id} | C9: Answer every buyer question and convert to a lead. | D9: Buyer/Tenant | E9: Yes | F9: Dynamic (SSR) | G9: Breadcrumb, gallery, header, sticky contact, details grid, amenities, map, seller card, similar, FAQ, JSON-LD | H9: Property API, similar API, locality summary | I9: Yes | J9: NOT STARTED | K9: OBSERVED FROM RESEARCH
A10: Property expired | B10: /property/{slug}-p{id} (HTTP 410) | C10: Handle a removed listing without a dead end or an SEO penalty. | D10: Buyer/Tenant | E10: Yes (410) | F10: Dynamic (SSR) | G10: Explanation, similar active listings, search CTA | H10: Similar listings API | I10: Yes | J10: NOT STARTED | K10: OBSERVED FROM RESEARCH
A11: Locality hub | B11: /localities/{city}/{locality} | C11: Capture research-intent traffic and link into listings. | D11: Buyer/Tenant | E11: Yes | F11: Dynamic (SSR + ISR) | G11: Locality summary, listing rails by intent, nearby localities, map, stats | H11: Locality API, listing counts | I11: Yes | J11: NOT STARTED | K11: OBSERVED FROM RESEARCH
A12: City hub | B12: /localities/{city} | C12: Top-level geographic entry point and crawl distribution. | D12: Buyer/Tenant | E12: Yes | F12: Dynamic (SSR + ISR) | G12: Locality grid, popular searches, listing counts | H12: Locality API | I12: Yes | J12: NOT STARTED | K12: OBSERVED FROM RESEARCH
A13: Login / Register | B13: /login, /register | C13: Let users authenticate by phone OTP. | D13: All | E13: No (noindex) | F13: Dynamic | G13: Phone input, OTP input, role select, resend timer | H13: Auth API | I13: Yes | J13: NOT STARTED | K13: OBSERVED FROM RESEARCH
A14: Post property wizard | B14: /post-property | C14: Let a seller create a listing in under 8 minutes on a phone. | D14: Seller/Owner/Agent | E14: No (noindex) | F14: Dynamic | G14: Stepper, config-driven fields, map pin, uploader, completeness score, preview | H14: Listings API, media presign, places API | I14: Yes | J14: NOT STARTED | K14: OBSERVED FROM RESEARCH
A15: Post property landing | B15: /post-property-free | C15: Marketing page that converts owners into sellers. | D15: Seller/Owner | E15: Yes | F15: Static/ISR | G15: Value proposition, steps explainer, CTA, FAQ | H15: None | I15: Yes | J15: NOT STARTED | K15: PROPOSED
... A45: EMI calculator | B45: /home-loan/emi-calculator | C45: High-intent finance tool and SEO asset. DEFERRED to v2.2. | D45: Buyer | E45: Yes | F45: Static + client JS | G45: Calculator, results, related content | H45: None | I45: Yes | J45: NOT STARTED | K45: OBSERVED FROM RESEARCH

Sheet USER FLOWS
A1: USER FLOWS — step-by-step journeys, including what can go wrong
A2: Fifteen complete journeys for buyers, sellers and admins. The 'Possible Error' column is the most valuable part: these are the failures to design for and test.
A4: Flow | B4: Step No. | C4: Actor | D4: Action | E4: Screen | F4: System Response | G4: Next Step | H4: Possible Error | I4: Status
A5: A. Buyer searches for a property | B5: 1 | C5: Buyer | D5: Opens the site | E5: Homepage | F5: Homepage renders server-side with the search widget ready | G5: Step 2 | H5: Slow first load — must stay within the LCP budget | I5: NOT STARTED
A6: A. Buyer searches for a property | B6: 2 | C6: Buyer | D6: Chooses the Buy or Rent tab | E6: Homepage | F6: Search form reconfigures for the chosen intent | G6: Step 3 | H6: Wrong filter set shown if intent not applied | I6: NOT STARTED
A7: A. Buyer searches for a property | B7: 3 | C7: Buyer | D7: Types a city or locality name | E7: Homepage | F7: Typeahead returns grouped suggestions with result counts | G7: Step 4 | H7: No suggestions if the gazetteer lacks the place; stale results if requests are not cancelled | I7: NOT STARTED
A8: A. Buyer searches for a property | B8: 4 | C8: Buyer | D8: Selects one or more places | E8: Homepage | F8: Each selection becomes a removable chip | G8: Step 5 | H8: Duplicate chips if not de-duplicated | I8: NOT STARTED
A9: A. Buyer searches for a property | B9: 5 | C9: Buyer | D9: Presses Search | E9: Homepage | F9: Navigates to the SEO landing URL for that intent and place | G9: Step 6 | H9: Unknown place cannot resolve to a URL | I9: NOT STARTED
A10: A. Buyer searches for a property | B10: 6 | C10: System | D10: Renders results | E10: Search results | F10: Server-rendered results with count in H1 and title | G10: Flow B | H10: Zero results — must show the recovery ladder, never a blank page | I10: NOT STARTED
A11: B. Buyer filters results | B11: 1 | C11: Buyer | D11: Opens filters | E11: Search results (desktop rail / mobile sheet) | F11: Filter panel opens showing option counts | G11: Step 2 | H11: Counts wrong if facet semantics are incorrect | I11: NOT STARTED
A12: B. Buyer filters results | B12: 2 | C12: Buyer | D12: Sets a budget range | E12: Filter panel | F12: Result count preview updates live | G12: Step 3 | H12: Linear slider makes the common range unselectable | I12: NOT STARTED
A13: B. Buyer filters results | B13: 3 | C13: Buyer | D13: Selects BHK and property type | E13: Filter panel | F13: Counts for other facets recalculate | G13: Step 4 | H13: Zero-count options hidden instead of disabled — looks broken | I13: NOT STARTED
A14: B. Buyer filters results | B14: 4 | C14: Buyer | D14: Applies filters | E14: Filter panel | F14: URL updates; results refresh; chips appear | G14: Step 5 | H14: CRITICAL: must never navigate away, reset scroll or clear state | I14: NOT STARTED
A15: B. Buyer filters results | B15: 5 | C15: Buyer | D15: Changes sort order | E15: Search results | F15: Results reorder; explicit sort is respected exactly | G15: Step 6 | H15: Promoted listings interleaving into an explicit sort destroys trust | I15: NOT STARTED
A16: B. Buyer filters results | B16: 6 | C16: Buyer | D16: Removes a filter chip | E16: Search results | F16: That filter is removed and results refresh | G16: Flow C | H16: Back button behaviour inconsistent if history is mismanaged | I16: NOT STARTED
... A74: O. Admin handles a reported listing | B74: 5 | C74: System | D74: Closes the loop | E74: — | F74: Reporter informed; seller informed if action was taken | G74: End | H74: Reporter never hearing back, so stops reporting | I74: NOT STARTED

Sheet DATABASE
A1: DATABASE — proposed tables and what each one is for
A2: An ORIGINAL conceptual schema derived from the observed functionality. Build only the MVP tables first. 'PostGIS?' marks tables needing map/location capability.
A4: Table | B4: Purpose | C4: Important Fields | D4: Relationships | E4: Indexes | F4: PostGIS? | G4: MVP/Future | H4: Status | I4: Source
A5: USER | B5: Every person on the platform: buyer, seller, agent, builder or admin. | C5: id, public_id, phone (unique, verified_at), email, name, roles[], status, preferred_city_id, created_at, deleted_at | D5: 1:1 AGENT_PROFILE / BUILDER_PROFILE; 1:N PROPERTY, INQUIRY, FAVORITE | E5: phone (unique), email (unique), status | F5: No | G5: MVP | H5: NOT STARTED | I5: OBSERVED FROM RESEARCH
A6: AGENT_PROFILE | B6: Extra details for users acting as agents. | C6: user_id, agency_name, slug, rera_agent_id, verified_status, areas_served[], rating, response_rate | D6: 1:1 USER | E6: user_id (unique), slug (unique) | F6: No | G6: FUTURE (v1.4) | H6: NOT STARTED | I6: OBSERVED FROM RESEARCH
A7: BUILDER_PROFILE | B7: Extra details for developer accounts. | C7: user_id, name, slug, logo_media_id, established_year, rera_ids[], verified_status | D7: 1:1 USER; 1:N PROJECT | E7: user_id (unique), slug (unique) | F7: No | G7: FUTURE (v1.5) | H7: NOT STARTED | I7: OBSERVED FROM RESEARCH
A8: LOCATION | B8: The place hierarchy: country, state, city, zone, locality, society. The most important table in the system. | C8: id, public_id, parent_id, type, name, slug, full_slug, centroid, boundary, pincode, aliases[], listing_count, is_active | D8: Self-referencing tree; 1:N PROPERTY | E8: parent_id+type+is_active, slug, GIST(centroid), GIST(boundary) | F8: YES | G8: MVP | H8: NOT STARTED | I8: OBSERVED FROM RESEARCH
A9: PROPERTY | B9: A listing. The central fact table. | C9: id, public_id, slug, owner_user_id, posted_by, intent, segment, property_type_id, location_id, geo, geo_precision, bedrooms, bathrooms, carpet_area, builtup_area, super_area, area_unit, price, status, is_verified, completeness_score, published_at, expires_at | D9: N:1 USER, LOCATION, PROPERTY_TYPE; 1:N PROPERTY_MEDIA, INQUIRY, PRICE_HISTORY; M:N AMENITY | E9: (status,intent,segment,location_id,price) WHERE ACTIVE; GIST(geo); (published_at DESC); (owner_user_id,status) | F9: YES | G9: MVP | H9: NOT STARTED | I9: OBSERVED FROM RESEARCH
A10: PROPERTY_MEDIA | B10: Photos, videos and floor plans for a listing. One table with a kind discriminator. | C10: id, property_id, kind, storage_key, cdn_url, width, height, sort_order, is_primary, phash, moderation_status | D10: N:1 PROPERTY | E10: (property_id, sort_order), phash | F10: No | G10: MVP | H10: NOT STARTED | I10: OBSERVED FROM RESEARCH
A11: PROPERTY_TYPE | B11: Reference list of property types and the fields each requires. | C11: id, code, name, segment, required_fields[], is_active | D11: 1:N PROPERTY | E11: code (unique) | F11: No | G11: MVP | H11: NOT STARTED | I11: OBSERVED FROM RESEARCH
A12: AMENITY | B12: Reference list of amenities, grouped and filterable. | C12: id, code, name, category, applies_to_segments[], is_filterable, sort_order | D12: M:N PROPERTY via PROPERTY_AMENITY | E12: code (unique) | F12: No | G12: MVP | H12: NOT STARTED | I12: OBSERVED FROM RESEARCH
A13: PROPERTY_AMENITY | B13: Join table linking listings to amenities, with an optional value. | C13: property_id, amenity_id, value | D13: N:N join | E13: (property_id), (amenity_id) | F13: No | G13: MVP | H13: NOT STARTED | I13: OBSERVED FROM RESEARCH
A14: INQUIRY | B14: A lead. The monetisable event — model it explicitly from day one. | C14: id, property_id, from_user_id, to_user_id, type (QUERY/CONTACT_VIEW/CALLBACK/VISIT), contact_snapshot, source_surface, is_billable, dedupe_key, seller_status, seller_notes, created_at | D14: N:1 PROPERTY, USER (from and to) | E14: (to_user_id, created_at DESC), dedupe_key (UNIQUE) | F14: No | G14: MVP | H14: NOT STARTED | I14: OBSERVED FROM RESEARCH
A15: FAVORITE | B15: A buyer's saved listing. | C15: user_id, property_id, created_at, note | D15: N:N USER-PROPERTY | E15: PK (user_id, property_id), (property_id) | F15: No | G15: MVP | H15: NOT STARTED | I15: OBSERVED FROM RESEARCH
... A36: OUTBOX | B36: Transactional outbox so events are published reliably. | C36: id, aggregate_type, aggregate_id, event_type, payload, published_at, created_at | D36: — | E36: (published_at NULLS FIRST, created_at) | F36: No | G36: MVP | H36: NOT STARTED | I36: OBSERVED FROM RESEARCH

Sheet API CHECKLIST
A1: API CHECKLIST — the planned endpoints (do NOT build these yet)
A2: This is the plan, not an instruction to start coding. 'Error Cases' matter as much as the success path — they are what makes an API feel reliable.
A4: API ID | B4: Module | C4: Method | D4: Endpoint | E4: Purpose | F4: Authentication | G4: Request | H4: Response | I4: Error Cases | J4: Database Tables | K4: MVP/Future | L4: Status
A5: API-01 | B5: Auth | C5: POST | D5: /auth/otp/request | E5: Send a one-time code to a phone number. | F5: Public | G5: {phone, purpose} | H5: {challenge_id, expires_in} | I5: 429 rate limited; 400 invalid phone; 503 SMS provider down | J5: OTP_CHALLENGE | K5: MVP | L5: NOT STARTED
A6: API-02 | B6: Auth | C6: POST | D6: /auth/otp/verify | E6: Verify the code and issue a session. | F6: Public | G6: {challenge_id, code} | H6: {access_token, refresh_token, user} | I6: 400 wrong code; 410 expired; 429 too many attempts | J6: OTP_CHALLENGE, USER, SESSION | K6: MVP | L6: NOT STARTED
A7: API-03 | B7: Auth | C7: POST | D7: /auth/refresh | E7: Exchange a refresh token for a new access token. | F7: Refresh token | G7: {refresh_token} | H7: {access_token, refresh_token} | I7: 401 invalid; 403 reuse detected (revoke all) | J7: SESSION | K7: MVP | L7: NOT STARTED
A8: API-04 | B8: Auth | C8: POST | D8: /auth/logout | E8: End the current session. | F8: Bearer | G8: {} | H8: 204 | I8: 401 unauthenticated | J8: SESSION | K8: MVP | L8: NOT STARTED
A9: API-05 | B9: User | C9: GET | D9: /me | E9: Return the signed-in user's profile. | F9: Bearer | G9: — | H9: {user} | I9: 401 | J9: USER | K9: MVP | L9: NOT STARTED
A10: API-06 | B10: User | C10: PATCH | D10: /me | E10: Update profile details. | F10: Bearer | G10: {name, email} | H10: {user} | I10: 400 validation; 409 email taken | J10: USER | K10: MVP | L10: NOT STARTED
A11: API-07 | B11: User | C11: POST | D11: /me/phone/change | E11: Change phone number with re-verification. | F11: Bearer | G11: {new_phone, challenge_id, code} | H11: {user} | I11: 400; 409 number in use | J11: USER, OTP_CHALLENGE, SESSION | K11: MVP | L11: NOT STARTED
A12: API-08 | B12: User | C12: POST | D12: /me/delete | E12: Request account deletion (data-protection right). | F12: Bearer | G12: {reason} | H12: {request_id, effective_at} | I12: 401; 409 active obligations | J12: USER | K12: MVP | L12: NOT STARTED
A13: API-09 | B13: Places | C13: GET | D13: /places/suggest | E13: Autocomplete cities, localities and societies. | F13: Public | G13: ?q=&limit=&city_id= | H13: [{id, type, label, path, listing_count}] | I13: 400 query too short | J13: PLACE_SUGGEST | K13: MVP | L13: NOT STARTED
A14: API-10 | B14: Places | C14: GET | D14: /places/{id} | E14: Return a place and its ancestors. | F14: Public | G14: — | H14: {place, ancestors[]} | I14: 404 | J14: LOCATION | K14: MVP | L14: NOT STARTED
A15: API-11 | B15: Search | C15: GET | D15: /search | E15: Return filtered, sorted, paginated listings. | F15: Public | G15: Normalised filter params + sort + page | H15: {results[], total, page, facets_summary} | I15: 400 invalid filter; 422 unknown place | J15: PROPERTY, LOCATION | K15: MVP | L15: NOT STARTED
... A54: API-50 | B54: Health | C54: GET | D54: /health | E54: Liveness and dependency check for monitoring. | F54: Public | G54: — | H54: {status, db, cache, version} | I54: 503 dependency down | J54: — | K54: MVP | L54: NOT STARTED

Sheet UI-UX CHECKLIST
A1: UI/UX CHECKLIST — design system and interface work
A2: The design system must be ORIGINAL. Extract principles from the research, never the competitor's colours, fonts or visual identity.
A4: Area | B4: Item | C4: What To Build | D4: Why It Matters | E4: MVP/Future | F4: Status | G4: Source
A5: Design system | B5: Design tokens | C5: Define colour, spacing, radius and elevation as named variables. | D5: Stops the interface drifting into inconsistency; makes dark mode cheap later. | E5: MVP | F5: NOT STARTED | G5: OBSERVED FROM RESEARCH
A6: Design system | B6: Original visual identity | C6: Create a colour palette and identity that is entirely your own. | D6: Copying a competitor's trade dress is the one part of this project with real legal exposure. | E6: MVP | F6: NOT STARTED | G6: OBSERVED FROM RESEARCH
A7: Typography | B7: Font family | C7: Choose one UI font with Indic script coverage if localisation is ever planned. | D7: Font changes late are disruptive and affect performance. | E7: MVP | F7: NOT STARTED | G7: OBSERVED FROM RESEARCH
A8: Typography | B8: Type scale | C8: Adopt a consistent scale (e.g. 12/14/16/18/20/25/31/39/49). | D8: Arbitrary font sizes make a UI look amateur. | E8: MVP | F8: NOT STARTED | G8: OBSERVED FROM RESEARCH
A9: Typography | B9: Tabular numerals | C9: Enable tabular figures for price, area and statistics. | D9: Numbers in lists must align to be comparable at a glance. | E9: MVP | F9: NOT STARTED | G9: OBSERVED FROM RESEARCH
A10: Colour | B10: Semantic tokens | C10: Name colours by role (primary, trust, danger) not by hue. | D10: Lets you change the palette without touching components. | E10: MVP | F10: NOT STARTED | G10: OBSERVED FROM RESEARCH
A11: Colour | B11: Contrast compliance | C11: Meet WCAG AA contrast on all text. | D11: Legal requirement and readability on phones in daylight. | E11: MVP | F11: NOT STARTED | G11: OBSERVED FROM RESEARCH
A12: Colour | B12: Never colour alone | C12: Pair every colour-coded meaning with an icon or text. | D12: Colour-blind users cannot decode colour-only signals. | E12: MVP | F12: NOT STARTED | G12: OBSERVED FROM RESEARCH
A13: Colour | B13: Dark mode tokens | C13: Define the dark palette from the start, even if shipped later. | D13: Retrofitting dark mode is far harder than planning for it. | E13: FUTURE | F13: NOT STARTED | G13: OBSERVED FROM RESEARCH
A14: Spacing | B14: 4px spacing scale | C14: Use 4/8/12/16/24/32/48/64 only. | D14: Consistent rhythm is most of what makes a UI feel designed. | E14: MVP | F14: NOT STARTED | G14: OBSERVED FROM RESEARCH
A15: Spacing | B15: Grid and containers | C15: Define container widths and column counts per breakpoint. | D15: Keeps layouts predictable across pages. | E15: MVP | F15: NOT STARTED | G15: OBSERVED FROM RESEARCH
... A72: Motion | B72: No hover dependencies | C72: Nothing reachable only by hover. | D72: Touch devices have no hover. | E72: MVP | F72: NOT STARTED | G72: OBSERVED FROM RESEARCH

Sheet SEO CHECKLIST
A1: SEO CHECKLIST — how people will find the site
A2: Read this BEFORE building any page. URL structure and rendering decisions cannot be retrofitted cheaply. 'LATER' items are the programmatic scale-up after launch.
A4: Area | B4: Item | C4: What To Do | D4: Why It Matters | E4: MVP/Later | F4: Status | G4: Source
A5: URL architecture | B5: Design routes before building | C5: Agree every public URL pattern in Phase 2. | D5: Retrofitting SEO-grade URLs onto a finished app is effectively a rewrite. | E5: MVP | F5: NOT STARTED | G5: OBSERVED FROM RESEARCH
A6: URL architecture | B6: Keyword-rich readable slugs | C6: Put intent, config, type and place into the URL. | D6: Observed on the incumbent; the slug carries the query terms users type. | E6: MVP | F6: NOT STARTED | G6: OBSERVED FROM RESEARCH
A7: URL architecture | B7: Typed ID suffix | C7: Append a short typed ID to detail URLs (e.g. -p12345). | D7: Guarantees uniqueness so slugs can be regenerated without breaking links. | E7: MVP | F7: NOT STARTED | G7: OBSERVED FROM RESEARCH
A8: URL architecture | B8: Two separate surfaces | C8: Pretty SSR URLs are indexable; /search query URLs are not. | D8: Keeps indexation controlled while still offering an app-like experience. | E8: MVP | F8: NOT STARTED | G8: OBSERVED FROM RESEARCH
A9: URL architecture | B9: Avoid subdomains | C9: Keep builders, projects and agents on the main domain as paths. | D9: Subdomains split authority and complicate analytics and sessions. | E9: MVP | F9: NOT STARTED | G9: OBSERVED FROM RESEARCH
A10: Canonical URLs | B10: Canonical on every page | C10: Point each filtered variant to its cleanest indexable form. | D10: Prevents duplicate-content dilution across thousands of combinations. | E10: MVP | F10: NOT STARTED | G10: OBSERVED FROM RESEARCH
A11: Canonical URLs | B11: Self-canonical on detail pages | C11: Each listing canonicalises to itself. | D11: Avoids accidental consolidation onto the wrong URL. | E11: MVP | F11: NOT STARTED | G11: OBSERVED FROM RESEARCH
A12: Index strategy | B12: Allowlist indexable facets | C12: Only named filter combinations may be indexed. | D12: Uncontrolled facet indexation is the classic cause of portal demotion. | E12: MVP | F12: NOT STARTED | G12: OBSERVED FROM RESEARCH
A13: Index strategy | B13: noindex the app surface | C13: The interactive /search route must not be indexed. | D13: It duplicates the landing pages with unstable parameters. | E13: MVP | F13: NOT STARTED | G13: OBSERVED FROM RESEARCH
A14: Thin content | B14: Minimum inventory gate | C14: Only index a page above an inventory threshold. | D14: Thousands of near-empty pages are a liability, not an asset. | E14: MVP | F14: NOT STARTED | G14: OBSERVED FROM RESEARCH
A15: Thin content | B15: Redirect below-threshold pages | C15: Send them to the parent page with nearby inventory shown. | D15: Preserves the user experience without indexing an empty page. | E15: MVP | F15: NOT STARTED | G15: OBSERVED FROM RESEARCH
... A51: Hreflang | B51: Multi-language tags | C51: Only if multi-language is ever built. | D51: Not applicable to a single-language launch. | E51: FUTURE | F51: NOT STARTED | G51: PROPOSED

Sheet SECURITY CHECKLIST
A1: SECURITY CHECKLIST — protecting users, data and the business model
A2: Every CRITICAL item must be DONE before launch. Nothing here involves bypassing anyone else's security — these are controls for YOUR system.
A4: Area | B4: Control | C4: What To Do | D4: Why It Matters | E4: Priority | F4: Status | G4: Source
A5: Authentication | B5: OTP as primary login | C5: Phone-based one-time codes as the main login method. | D5: Appropriate for the Indian market where phone is the primary identity. | E5: CRITICAL | F5: NOT STARTED | G5: OBSERVED FROM RESEARCH
A6: Authentication | B6: Hash OTP codes at rest | C6: Store a hash of the code, never the code itself. | D6: A database leak must not expose live codes. | E6: CRITICAL | F6: NOT STARTED | G6: PROPOSED
A7: Authentication | B7: Single-use codes | C7: Consume the code on first successful use. | D7: Prevents replay of an intercepted code. | E7: CRITICAL | F7: NOT STARTED | G7: OBSERVED FROM RESEARCH
A8: Authentication | B8: Short expiry | C8: Expire codes within a few minutes. | D8: Limits the window for interception. | E8: CRITICAL | F8: NOT STARTED | G8: OBSERVED FROM RESEARCH
A9: Authentication | B9: Attempt limits | C9: Lock the challenge after a small number of wrong attempts. | D9: Prevents brute-forcing a 6-digit code. | E9: CRITICAL | F9: NOT STARTED | G9: OBSERVED FROM RESEARCH
